Workbook
Name _Toc301930468: #REF!
Name _Toc301930478: #REF!
Name ACTION: #REF!
Name Excel_BuiltIn__FilterDatabase: Module1!$A$8:$H$16

Sheet Cover
B2: TEST CASE
B4: Project Name | C4: Dò vé số | F4: Creator | G4: DucNVFX14814
B5: Project Code | C5: Lab301x | F5: Reviewer/Approver | G5: ToanHK(Mentor)
B6: Document Code | C6: =C5&"_"&"CN3_TestCase"&"_"&"v1.0" -> Lab301x_CN3_TestCase_v1.0 | F6: Issue Date | G6: 01/10/2026
F7: Version | G7: V1.0
B10: Record of change
B11: Effective Date | C11: Version | D11: Change Item | E11: *A,D,M | F11: Change description | G11: Reference
B12: 01/10/2026 | C12: 1.0 | D12: Khởi tạo | E12: A | F12: Tạo mới Test Case cho CN3 - Thực hiện dò vé số (NO_USER, USER; ADMIN không hỗ trợ) | G12: DucNVFX14814_SRS, DucNVFX14814_CN3_Screen_Design

Sheet TestDesign
A1: Requirement Level 1 | B1: Requirement Level 2 | C1: Requirement Level 3 | D1: Test Criteria | E1: Test Type | F1: Note
A2: CN3 - Dò vé số (NO_USER) | B2: Dò vé thành công | C2: Thành công | D2: Dò vé trúng giải (không phải giải Đặc biệt) | E2: Function | F2: Cần có vé dò PUBLISH của tỉnh/ngày chọn; biết trước số vé trúng giải
D3: Dò vé không trúng giải | E3: Function | F3: Cần có vé dò PUBLISH của tỉnh/ngày chọn
D4: Dò vé trúng giải Đặc biệt | E4: Function | F4: Cần có vé dò PUBLISH của tỉnh/ngày chọn; biết số giải Đặc biệt
D5: Dò vé trúng nhiều giải | E5: Function | F5: Cần có vé dò PUBLISH của tỉnh/ngày chọn; biết số vé trúng nhiều giải
D6: Dò vé của tỉnh miền Trung / miền Nam (6 chữ số) | E6: Function | F6: Cần có vé dò PUBLISH của tỉnh miền Trung/Nam
D7: NO_USER dò vé không được lưu lịch sử | E7: Function | F7: Thực hiện sau khi dò vé ở trên
B8: Chọn miền / tỉnh và định dạng số vé | C8: Thành công | D8: Lọc danh sách Tỉnh theo Miền | E8: Function
D9: Nhãn và độ dài số vé thay đổi theo tỉnh | E9: Function
D10: Giao diện NO_USER chỉ dò được 1 vé | E10: Function
B11: Dò vé không thành công | C11: Không thành công | D11: Chưa chọn Tỉnh | E11: Function
D12: Để trống số vé | E12: Function
D13: Số vé sai số lượng chữ số | E13: Function
D14: Số vé chứa ký tự không phải chữ số | E14: Function
D15: Chọn Ngày quay số trong tương lai | E15: Function
D16: Vé dò chưa công bố (UNPUBLISH) | E16: Function | F16: Cần có 1 vé dò UNPUBLISH
D17: Ngày chưa có vé dò trong hệ thống | E17: Function
A18: CN3 - Dò vé số và lịch sử dò (USER) | B18: Dò vé thành công | C18: Thành công | D18: Dò 1 vé trúng giải | E18: Function | F18: Cần có vé dò PUBLISH của tỉnh/ngày chọn; biết số vé trúng giải
D19: Dò nhiều vé cùng lúc | E19: Function | F19: Cần có vé dò PUBLISH của tỉnh/ngày chọn
D20: Dò nhiều vé nhưng không vé nào trúng | E20: Function | F20: Cần có vé dò PUBLISH của tỉnh/ngày chọn
D21: Nhập các số vé cách nhau bằng dấu phẩy | E21: Function | F21: Cần có vé dò PUBLISH của tỉnh/ngày chọn
D22: Nhập trùng số vé | E22: Function | F22: Cần có vé dò PUBLISH của tỉnh/ngày chọn
D23: Dò đúng 20 số vé | E23: Function | F23: Cần có vé dò PUBLISH của tỉnh/ngày chọn
D24: Dò vé trúng giải Đặc biệt | E24: Function | F24: Cần có vé dò PUBLISH của tỉnh/ngày chọn; biết số giải Đặc biệt
D25: Dò vé của tỉnh miền Trung / miền Nam (6 chữ số) | E25: Function | F25: Cần có vé dò PUBLISH của tỉnh miền Trung/Nam
D26: Kết quả dò được lưu vào lịch sử | E26: Function | F26: Thực hiện sau khi dò vé
B27: Dò vé không thành công | C27: Không thành công | D27: Chưa chọn Tỉnh | E27: Function
D28: Để trống danh sách số vé | E28: Function
D29: Chỉ nhập khoảng trắng / xuống dòng | E29: Function
D30: Có số vé sai số lượng chữ số | E30: Function
D31: Có số vé chứa ký tự không phải chữ số | E31: Function
D32: Nhập quá 20 số vé | E32: Function
D33: Dữ liệu nhập quá dài | E33: Function
D34: Chọn Ngày quay số trong tương lai | E34: Function
D35: Vé dò chưa công bố (UNPUBLISH) | E35: Function | F35: Cần có 1 vé dò UNPUBLISH
D36: Ngày chưa có vé dò trong hệ thống | E36: Function
B37: Xem lại lịch sử dò vé | C37: Thành công | D37: Xem lịch sử mặc định | E37: Function | F37: USER đã có lượt dò trong tháng
D38: Hiển thị lượt dò trúng / không trúng giải | E38: Function | F38: Cần có cả lượt trúng và không trúng
D39: Lọc theo miền / tỉnh | E39: Function
D40: Lọc theo khoảng ngày dò | E40: Function
...

Sheet Test case List
D1: TEST CASE LIST
B3: Project Name | D3: =Cover!C4 -> Dò vé số
B4: Project Code | D4: =Cover!C5 -> Lab301x
B5: Test Environment Setup Description | D5: 1. Web server: Apache Tomcat 9 2. Database: MySQL 8 3. Web Browser: Chrome/Edge mới nhất 4. Dữ liệu: đã có các vé dò PUBLISH / UNPUBLISH của nhiều tỉnh, 2 tài khoản USER và 1 tài khoản ADMIN
B8: No | C8: Function Name | D8: Sheet Name | E8: Description | F8: Pre-Condition
B9: 1 | C9: Dò vé số (NO_USER) | D9: Module1 | E9: Dò 1 số vé không cần đăng nhập, không lưu lịch sử | F9: Có vé dò đã công bố
B10: 2 | C10: Dò vé số (USER) | D10: Module2 | E10: Dò 1 hoặc nhiều số vé (tối đa 20), lưu lịch sử dò | F10: Đã đăng nhập USER; có vé dò đã công bố
B11: 3 | C11: Lịch sử dò vé (USER) | D11: Module2 | E11: Xem, lọc, phân trang các lượt dò trước đó | F11: Đã đăng nhập USER

Sheet Module1
A2: Module Code | B2: Module1 | J2: Passed
A3: Test requirement | B3: Yêu cầu 2 (NO_USER): Dò vé số - nhập 1 số vé, đối chiếu với vé dò đã công bố, hiển thị kết quả trúng giải / không trúng giải. | J3: Failed
A4: Tester | J4: Blocked
A5: Passed | B5: Failed | C5: Untested | D5: Blocked | E5: Skipped | F5: Number of Test cases | J5: Untested
A6: =COUNTIF(F9:F995,"Passed") -> 16 | B6: =COUNTIF(F9:F995,"Failed") -> 0 | C6: =F6-E6-D6-B6-A6 -> 0 | D6: =COUNTIF(F$9:F$995,"Blocked") -> 0 | E6: =COUNTIF(F$9:F$995,"Skipped") -> 0 | F6: =COUNTA(A9:A995) -> 16 | J6: Skipped
A8: ID | B8: Test Case Description | C8: Test Case Procedure | D8: Expected Output | E8: Inter-test case Dependence | F8: Result | G8: Test date | H8: Note
B9: Dò vé thành công
A10: =IF(OR(B10<>"",D10<>""),"[" &TEXT($B$2,"##")&"-"&TEXT(1,"00")&"]","") -> [Module1-01] | B10: Dò vé trúng giải (không phải giải Đặc biệt) | C10: 1. Chưa đăng nhập, vào trang chủ / menu "Dò vé số". 2. Chọn Miền, Tỉnh và Ngày quay số của 1 vé dò đã công bố. 3. Nhập số vé 5 chữ số (miền Bắc) có đuôi trùng 1 giải (ví dụ 2 số cuối trùng Giải bảy). 4. Bấm "Dò vé". | D10: Hiển thị bảng "Kết quả dò của bạn": số vé, tên giải trúng (trạng thái xanh) kèm số tiền, "Tổng tiền thưởng" đúng; bên dưới hiển thị bảng kết quả xổ số của tỉnh/ngày đã chọn. | E10: Cần có vé dò PUBLISH của tỉnh/ngày chọn | F10: Passed | G10: 01/10/2026
A11: =IF(OR(B11<>"",D11<>""),"[" &TEXT($B$2,"##")&"-"&TEXT(2,"00")&"]","") -> [Module1-02] | B11: Dò vé không trúng giải | C11: 1. Chọn Tỉnh và Ngày quay số của 1 vé dò đã công bố. 2. Nhập 1 số vé chắc chắn không trùng đuôi với giải nào. 3. Bấm "Dò vé". | D11: Cột Kết quả hiển thị "Không trúng giải", Tổng tiền thưởng hiển thị "-"; vẫn hiển thị bảng kết quả xổ số của ngày đó. | E11: Cần có vé dò PUBLISH của tỉnh/ngày chọn | F11: Passed | G11: 01/10/2026
A12: =IF(OR(B12<>"",D12<>""),"[" &TEXT($B$2,"##")&"-"&TEXT(3,"00")&"]","") -> [Module1-03] | B12: Dò vé trúng giải Đặc biệt | C12: 1. Chọn Tỉnh/Ngày của 1 vé dò đã công bố. 2. Nhập số vé trùng đủ 5 chữ số với giải Đặc biệt. 3. Bấm "Dò vé". | D12: Chỉ hiển thị giải Đặc biệt với số tiền tương ứng, không cộng thêm các giải khác dù đuôi số vé có trùng. | E12: Cần có vé dò PUBLISH của tỉnh/ngày chọn; biết số giải Đặc biệt | F12: Passed | G12: 01/10/2026
A13: =IF(OR(B13<>"",D13<>""),"[" &TEXT($B$2,"##")&"-"&TEXT(4,"00")&"]","") -> [Module1-04] | B13: Dò vé trúng nhiều giải | C13: 1. Chọn Tỉnh/Ngày của 1 vé dò đã công bố. 2. Nhập số vé có đuôi trùng với từ 2 giải trở lên (không có giải Đặc biệt). 3. Bấm "Dò vé". | D13: Mỗi giải trúng hiển thị 1 dòng (trạng thái + số tiền); Tổng tiền thưởng bằng tổng tiền các giải trúng. | E13: Cần có vé dò PUBLISH của tỉnh/ngày chọn; biết số vé trúng nhiều giải | F13: Passed | G13: 01/10/2026
A14: =IF(OR(B14<>"",D14<>""),"[" &TEXT($B$2,"##")&"-"&TEXT(5,"00")&"]","") -> [Module1-05] | B14: Dò vé của tỉnh miền Trung / miền Nam (6 chữ số) | C14: 1. Chọn Miền Nam (hoặc Trung), chọn 1 tỉnh, chọn ngày của vé dò đã công bố. 2. Nhập số vé 6 chữ số. 3. Bấm "Dò vé". | D14: Dò thành công, hiển thị kết quả đúng theo đuôi 6 chữ số và mức thưởng của miền tương ứng. | E14: Cần có vé dò PUBLISH của tỉnh miền Trung/Nam | F14: Passed | G14: 01/10/2026
A15: =IF(OR(B15<>"",D15<>""),"[" &TEXT($B$2,"##")&"-"&TEXT(6,"00")&"]","") -> [Module1-06] | B15: NO_USER dò vé không được lưu lịch sử | C15: 1. Chưa đăng nhập, dò 1 vé thành công. 2. Đăng nhập bằng 1 tài khoản USER, vào "Lịch sử dò vé". | D15: Lịch sử của USER không có lượt dò vừa thực hiện khi chưa đăng nhập. | E15: Thực hiện sau khi dò vé ở trên | F15: Passed | G15: 01/10/2026
B16: Chọn miền / tỉnh và định dạng số vé
A17: =IF(OR(B17<>"",D17<>""),"[" &TEXT($B$2,"##")&"-"&TEXT(7,"00")&"]","") -> [Module1-07] | B17: Lọc danh sách Tỉnh theo Miền | C17: 1. Vào trang Dò vé số. 2. Chọn 1 Miền bất kỳ. | D17: Danh sách Tỉnh chỉ còn các tỉnh thuộc miền đã chọn; chọn "Tất cả miền" thì hiển thị đủ các tỉnh. | F17: Passed | G17: 01/10/2026
A18: =IF(OR(B18<>"",D18<>""),"[" &TEXT($B$2,"##")&"-"&TEXT(8,"00")&"]","") -> [Module1-08] | B18: Nhãn và độ dài số vé thay đổi theo tỉnh | C18: 1. Chọn 1 tỉnh miền Bắc. 2. Quan sát ô Số vé số. 3. Chọn 1 tỉnh miền Trung/Nam và quan sát lại. | D18: Miền Bắc: nhãn "Số vé số (5 chữ số)", chỉ nhập tối đa 5 ký tự. Miền Trung/Nam: nhãn "Số vé số (6 chữ số)", tối đa 6 ký tự. Khi chưa chọn tỉnh: "5 hoặc 6 chữ số". | F18: Passed | G18: 01/10/2026
A19: =IF(OR(B19<>"",D19<>""),"[" &TEXT($B$2,"##")&"-"&TEXT(9,"00")&"]","") -> [Module1-09] | B19: Giao diện NO_USER chỉ dò được 1 vé | C19: 1. Chưa đăng nhập, vào trang Dò vé số. | D19: Chỉ có 1 ô nhập số vé (không có ô nhập danh sách nhiều vé) và có dòng gợi ý "Đăng nhập để dò được nhiều vé cùng lúc và xem lại lịch sử dò vé." | F19: Passed | G19: 01/10/2026
B20: Dò vé không thành công
A21: =IF(OR(B21<>"",D21<>""),"[" &TEXT($B$2,"##")&"-"&TEXT(10,"00")&"]","") -> [Module1-10] | B21: Chưa chọn Tỉnh | C21: 1. Để Tỉnh ở "-- Chọn tỉnh --". 2. Nhập ngày và số vé, bấm "Dò vé". | D21: Form không được gửi đi, trình duyệt yêu cầu chọn tỉnh (trường bắt buộc). | F21: Passed | G21: 01/10/2026
A22: =IF(OR(B22<>"",D22<>""),"[" &TEXT($B$2,"##")&"-"&TEXT(11,"00")&"]","") -> [Module1-11] | B22: Để trống số vé | C22: 1. Chọn tỉnh, ngày hợp lệ. 2. Để trống ô Số vé số, bấm "Dò vé". | D22: Form không được gửi đi, trình duyệt yêu cầu nhập số vé (trường bắt buộc). | F22: Passed | G22: 01/10/2026
A23: =IF(OR(B23<>"",D23<>""),"[" &TEXT($B$2,"##")&"-"&TEXT(12,"00")&"]","") -> [Module1-12] | B23: Số vé sai số lượng chữ số | C23: 1. Chọn tỉnh miền Bắc. 2. Nhập số vé 4 chữ số (hoặc chọn tỉnh miền Nam và nhập 5 chữ số). 3. Bấm "Dò vé". | D23: Form không được gửi đi, trình duyệt báo số vé không đúng định dạng (phải đủ 5 chữ số với miền Bắc, 6 chữ số với miền Trung/Nam). | F23: Passed | G23: 01/10/2026
A24: =IF(OR(B24<>"",D24<>""),"[" &TEXT($B$2,"##")&"-"&TEXT(13,"00")&"]","") -> [Module1-13] | B24: Số vé chứa ký tự không phải chữ số | C24: 1. Chọn tỉnh, nhập số vé có chữ cái hoặc ký tự đặc biệt (ví dụ "12a45"). 2. Bấm "Dò vé". | D24: Form không được gửi đi, trình duyệt báo số vé không đúng định dạng. | F24: Passed | G24: 01/10/2026
A25: =IF(OR(B25<>"",D25<>""),"[" &TEXT($B$2,"##")&"-"&TEXT(14,"00")&"]","") -> [Module1-14] | B25: Chọn Ngày quay số trong tương lai | C25: 1. Chọn Ngày quay số sau ngày hiện tại. 2. Bấm "Dò vé". | D25: Hiển thị lỗi "Giá trị phải là ngày hiện tại hoặc sớm hơn."; không thực hiện dò. | F25: Passed | G25: 01/10/2026
A26: =IF(OR(B26<>"",D26<>""),"[" &TEXT($B$2,"##")&"-"&TEXT(15,"00")&"]","") -> [Module1-15] | B26: Vé dò chưa công bố (UNPUBLISH) | C26: 1. Chọn tỉnh và ngày của 1 vé dò đã lưu nhưng chưa công bố. 2. Nhập số vé hợp lệ, bấm "Dò vé". | D26: Hiển thị lỗi "Vé dò [tên tỉnh] ngày [dd/MM/yyyy] không tồn tại hoặc chưa được công bố kết quả." | E26: Cần có 1 vé dò UNPUBLISH | F26: Passed | G26: 01/10/2026
A27: =IF(OR(B27<>"",D27<>""),"[" &TEXT($B$2,"##")&"-"&TEXT(16,"00")&"]","") -> [Module1-16] | B27: Ngày chưa có vé dò trong hệ thống | C27: 1. Chọn tỉnh và 1 ngày chưa có vé dò nào trong hệ thống. 2. Nhập số vé hợp lệ, bấm "Dò vé". | D27: Hiển thị lỗi "Vé dò [tên tỉnh] ngày [dd/MM/yyyy] không tồn tại hoặc chưa được công bố kết quả." | F27: Passed | G27: 01/10/2026

Sheet Module2
A2: Module Code | B2: Module2 | J2: Passed
A3: Test requirement | B3: Yêu cầu 3 (USER): Dò một hoặc nhiều vé số của một tỉnh, hiển thị kết quả, lưu và xem lại lịch sử dò vé (có lọc, phân trang). | J3: Failed
A4: Tester | J4: Blocked
A5: Passed | B5: Failed | C5: Untested | D5: Blocked | E5: Skipped | F5: Number of Test cases | J5: Untested
A6: =COUNTIF(F9:F991,"Passed") -> 28 | B6: =COUNTIF(F9:F991,"Failed") -> 0 | C6: =F6-E6-D6-B6-A6 -> 0 | D6: =COUNTIF(F$9:F$991,"Blocked") -> 0 | E6: =COUNTIF(F$9:F$991,"Skipped") -> 0 | F6: =COUNTA(A9:A991) -> 28 | J6: Skipped
A8: ID | B8: Test Case Description | C8: Test Case Procedure | D8: Expected Output | E8: Inter-test case Dependence | F8: Result | G8: Test date | H8: Note
B9: Dò vé thành công
A10: =IF(OR(B10<>"",D10<>""),"[" &TEXT($B$2,"##")&"-"&TEXT(1,"00")&"]","") -> [Module2-01] | B10: Dò 1 vé trúng giải | C10: 1. Đăng nhập USER, vào menu "Dò vé số". 2. Chọn Tỉnh, Ngày quay số của 1 vé dò đã công bố. 3. Nhập 1 số vé trúng giải vào ô Danh sách số vé số. 4. Bấm "Dò vé". | D10: Hiển thị "Kết quả dò của bạn" với tên giải và số tiền đúng; bên dưới hiển thị bảng kết quả xổ số của tỉnh/ngày. | E10: Cần có vé dò PUBLISH của tỉnh/ngày chọn; biết số vé trúng giải | F10: Passed | G10: 01/10/2026
A11: =IF(OR(B11<>"",D11<>""),"[" &TEXT($B$2,"##")&"-"&TEXT(2,"00")&"]","") -> [Module2-02] | B11: Dò nhiều vé cùng lúc | C11: 1. Chọn Tỉnh, Ngày của 1 vé dò đã công bố. 2. Nhập nhiều số vé, mỗi dòng 1 số (trong đó có ít nhất 1 vé trúng). 3. Bấm "Dò vé". | D11: Mỗi số vé hiển thị 1 dòng kết quả đúng; chân bảng hiển thị "Tổng tiền trúng thưởng" bằng tổng tiền của các vé trúng. | E11: Cần có vé dò PUBLISH của tỉnh/ngày chọn | F11: Passed | G11: 01/10/2026
A12: =IF(OR(B12<>"",D12<>""),"[" &TEXT($B$2,"##")&"-"&TEXT(3,"00")&"]","") -> [Module2-03] | B12: Dò nhiều vé nhưng không vé nào trúng | C12: 1. Nhập nhiều số vé chắc chắn không trúng. 2. Bấm "Dò vé". | D12: Tất cả các dòng hiển thị "Không trúng giải", tiền "-"; không hiển thị dòng "Tổng tiền trúng thưởng". | E12: Cần có vé dò PUBLISH của tỉnh/ngày chọn | F12: Passed | G12: 01/10/2026
A13: =IF(OR(B13<>"",D13<>""),"[" &TEXT($B$2,"##")&"-"&TEXT(4,"00")&"]","") -> [Module2-04] | B13: Nhập các số vé cách nhau bằng dấu phẩy | C13: 1. Nhập "12345, 67890" (hoặc 2 số cách nhau bằng dấu phẩy) vào ô danh sách số vé. 2. Bấm "Dò vé". | D13: Hệ thống tách thành từng số và hiển thị kết quả của từng số. | E13: Cần có vé dò PUBLISH của tỉnh/ngày chọn | F13: Passed | G13: 01/10/2026
A14: =IF(OR(B14<>"",D14<>""),"[" &TEXT($B$2,"##")&"-"&TEXT(5,"00")&"]","") -> [Module2-05] | B14: Nhập trùng số vé | C14: 1. Nhập cùng 1 số vé 2 lần (2 dòng giống nhau). 2. Bấm "Dò vé". | D14: Số vé trùng chỉ được dò 1 lần, kết quả hiển thị 1 dòng. | E14: Cần có vé dò PUBLISH của tỉnh/ngày chọn | F14: Passed | G14: 01/10/2026
A15: =IF(OR(B15<>"",D15<>""),"[" &TEXT($B$2,"##")&"-"&TEXT(6,"00")&"]","") -> [Module2-06] | B15: Dò đúng 20 số vé | C15: 1. Nhập 20 số vé khác nhau, hợp lệ. 2. Bấm "Dò vé". | D15: Dò thành công, hiển thị đủ 20 dòng kết quả. | E15: Cần có vé dò PUBLISH của tỉnh/ngày chọn | F15: Passed | G15: 01/10/2026
A16: =IF(OR(B16<>"",D16<>""),"[" &TEXT($B$2,"##")&"-"&TEXT(7,"00")&"]","") -> [Module2-07] | B16: Dò vé trúng giải Đặc biệt | C16: 1. Nhập số vé trùng đủ 5 chữ số với giải Đặc biệt (miền Bắc). 2. Bấm "Dò vé". | D16: Chỉ hiển thị giải Đặc biệt và số tiền tương ứng, không cộng dồn giải khác. | E16: Cần có vé dò PUBLISH của tỉnh/ngày chọn; biết số giải Đặc biệt | F16: Passed | G16: 01/10/2026
A17: =IF(OR(B17<>"",D17<>""),"[" &TEXT($B$2,"##")&"-"&TEXT(8,"00")&"]","") -> [Module2-08] | B17: Dò vé của tỉnh miền Trung / miền Nam (6 chữ số) | C17: 1. Chọn 1 tỉnh miền Trung/Nam và ngày của vé dò đã công bố. 2. Nhập các số vé 6 chữ số. 3. Bấm "Dò vé". | D17: Dò thành công, kết quả đúng theo đuôi 6 chữ số và mức thưởng của miền tương ứng. | E17: Cần có vé dò PUBLISH của tỉnh miền Trung/Nam | F17: Passed | G17: 01/10/2026
A18: =IF(OR(B18<>"",D18<>""),"[" &TEXT($B$2,"##")&"-"&TEXT(9,"00")&"]","") -> [Module2-09] | B18: Kết quả dò được lưu vào lịch sử | C18: 1. Dò N số vé thành công (N ≥ 1). 2. Vào menu "Lịch sử dò vé" (khoảng ngày bao gồm hôm nay). | D18: Có thêm N lượt dò mới, mỗi số vé 1 dòng, đúng số vé, kết quả và tổng tiền thưởng. | E18: Thực hiện sau khi dò vé | F18: Passed | G18: 01/10/2026
B19: Dò vé không thành công
A20: =IF(OR(B20<>"",D20<>""),"[" &TEXT($B$2,"##")&"-"&TEXT(10,"00")&"]","") -> [Module2-10] | B20: Chưa chọn Tỉnh | C20: 1. Để Tỉnh ở "-- Chọn tỉnh --". 2. Nhập số vé, bấm "Dò vé". | D20: Form không được gửi đi, trình duyệt yêu cầu chọn tỉnh (trường bắt buộc). | F20: Passed | G20: 01/10/2026
A21: =IF(OR(B21<>"",D21<>""),"[" &TEXT($B$2,"##")&"-"&TEXT(11,"00")&"]","") -> [Module2-11] | B21: Để trống danh sách số vé | C21: 1. Chọn tỉnh, ngày hợp lệ. 2. Để trống ô danh sách số vé, bấm "Dò vé". | D21: Form không được gửi đi, trình duyệt yêu cầu nhập số vé (trường bắt buộc). | F21: Passed | G21: 01/10/2026
A22: =IF(OR(B22<>"",D22<>""),"[" &TEXT($B$2,"##")&"-"&TEXT(12,"00")&"]","") -> [Module2-12] | B22: Chỉ nhập khoảng trắng / xuống dòng | C22: 1. Chọn tỉnh, ngày hợp lệ. 2. Chỉ nhập khoảng trắng hoặc xuống dòng vào ô danh sách số vé. 3. Bấm "Dò vé". | D22: Hiển thị lỗi "Vui lòng nhập ít nhất 1 số vé số." | F22: Passed | G22: 01/10/2026
A23: =IF(OR(B23<>"",D23<>""),"[" &TEXT($B$2,"##")&"-"&TEXT(13,"00")&"]","") -> [Module2-13] | B23: Có số vé sai số lượng chữ số | C23: 1. Chọn tỉnh miền Bắc. 2. Nhập danh sách có 1 số không đủ 5 chữ số (ví dụ "1234"). 3. Bấm "Dò vé". | D23: Hiển thị hộp thoại "Số vé "1234" không hợp lệ. Số vé phải gồm đúng 5 chữ số."; form không được gửi đi. | F23: Passed | G23: 01/10/2026
A24: =IF(OR(B24<>"",D24<>""),"[" &TEXT($B$2,"##")&"-"&TEXT(14,"00")&"]","") -> [Module2-14] | B24: Có số vé chứa ký tự không phải chữ số | C24: 1. Nhập danh sách có 1 số chứa chữ cái (ví dụ "12a45"). 2. Bấm "Dò vé". | D24: Hiển thị hộp thoại báo số vé không hợp lệ; form không được gửi đi. | F24: Passed | G24: 01/10/2026
A25: =IF(OR(B25<>"",D25<>""),"[" &TEXT($B$2,"##")&"-"&TEXT(15,"00")&"]","") -> [Module2-15] | B25: Nhập quá 20 số vé | C25: 1. Nhập 21 số vé khác nhau, hợp lệ. 2. Bấm "Dò vé". | D25: Hiển thị lỗi "Mỗi lần chỉ được dò tối đa 20 số vé (bạn đã nhập 21 số)." | F25: Passed | G25: 01/10/2026
A26: =IF(OR(B26<>"",D26<>""),"[" &TEXT($B$2,"##")&"-"&TEXT(16,"00")&"]","") -> [Module2-16] | B26: Dữ liệu nhập quá dài | C26: 1. Dán vào ô danh sách 1 chuỗi dài hơn 2000 ký tự (ví dụ lặp "12345," khoảng 350 lần). 2. Bấm "Dò vé". | D26: Hiển thị lỗi "Dữ liệu nhập quá dài, vui lòng chỉ nhập tối đa 20 số vé." | F26: Passed | G26: 01/10/2026
A27: =IF(OR(B27<>"",D27<>""),"[" &TEXT($B$2,"##")&"-"&TEXT(17,"00")&"]","") -> [Module2-17] | B27: Chọn Ngày quay số trong tương lai | C27: 1. Chọn Ngày quay số sau ngày hiện tại. 2. Bấm "Dò vé". | D27: Hiển thị lỗi "Giá trị phải là ngày hiện tại hoặc sớm hơn."; không thực hiện dò. | F27: Passed | G27: 01/10/2026
A28: =IF(OR(B28<>"",D28<>""),"[" &TEXT($B$2,"##")&"-"&TEXT(18,"00")&"]","") -> [Module2-18] | B28: Vé dò chưa công bố (UNPUBLISH) | C28: 1. Chọn tỉnh và ngày của 1 vé dò chưa công bố. 2. Nhập số vé hợp lệ, bấm "Dò vé". | D28: Hiển thị lỗi "Vé dò [tên tỉnh] ngày [dd/MM/yyyy] không tồn tại hoặc chưa được công bố kết quả."; không lưu lịch sử. | E28: Cần có 1 vé dò UNPUBLISH | F28: Passed | G28: 01/10/2026
A29: =IF(OR(B29<>"",D29<>""),"[" &TEXT($B$2,"##")&"-"&TEXT(19,"00")&"]","") -> [Module2-19] | B29: Ngày chưa có vé dò trong hệ thống | C29: 1. Chọn tỉnh và 1 ngày chưa có vé dò. 2. Nhập số vé hợp lệ, bấm "Dò vé". | D29: Hiển thị lỗi "Vé dò [tên tỉnh] ngày [dd/MM/yyyy] không tồn tại hoặc chưa được công bố kết quả." | F29: Passed | G29: 01/10/2026
B30: Xem lại lịch sử dò vé
A31: =IF(OR(B31<>"",D31<>""),"[" &TEXT($B$2,"##")&"-"&TEXT(20,"00")&"]","") -> [Module2-20] | B31: Xem lịch sử mặc định | C31: 1. Đăng nhập USER đã có lượt dò. 2. Vào menu "Lịch sử dò vé" (không chọn bộ lọc). | D31: Hiển thị các lượt dò từ đầu tháng hiện tại đến hôm nay, tất cả miền/tỉnh, mới nhất trước; bảng có các cột Miền, Tỉnh, Ngày quay số, Số vé đã dò, Kết quả, Tổng tiền thưởng, Thời điểm dò (dd/MM/yyyy HH:mm). | E31: USER đã có lượt dò trong tháng | F31: Passed | G31: 01/10/2026
A32: =IF(OR(B32<>"",D32<>""),"[" &TEXT($B$2,"##")&"-"&TEXT(21,"00")&"]","") -> [Module2-21] | B32: Hiển thị lượt dò trúng / không trúng giải | C32: 1. Xem lịch sử có cả lượt trúng và không trúng. | D32: Lượt trúng giải được tô nổi bật, hiển thị tổng tiền thưởng (định dạng có dấu chấm ngăn cách hàng nghìn); lượt không trúng hiển thị "-". | E32: Cần có cả lượt trúng và không trúng | F32: Passed | G32: 01/10/2026
A33: =IF(OR(B33<>"",D33<>""),"[" &TEXT($B$2,"##")&"-"&TEXT(22,"00")&"]","") -> [Module2-22] | B33: Lọc theo miền / tỉnh | C33: 1. Chọn 1 Miền, 1 Tỉnh. 2. Bấm "Tìm kiếm". | D33: Chỉ hiển thị các lượt dò của tỉnh đã chọn. | F33: Passed | G33: 01/10/2026
A34: =IF(OR(B34<>"",D34<>""),"[" &TEXT($B$2,"##")&"-"&TEXT(23,"00")&"]","") -> [Module2-23] | B34: Lọc theo khoảng ngày dò | C34: 1. Chọn Từ ngày / Đến ngày hợp lệ. 2. Bấm "Tìm kiếm". | D34: Chỉ hiển thị các lượt dò có thời điểm dò nằm trong khoảng ngày đã chọn. | F34: Passed | G34: 01/10/2026
A35: =IF(OR(B35<>"",D35<>""),"[" &TEXT($B$2,"##")&"-"&TEXT(24,"00")&"]","") -> [Module2-24] | B35: Từ ngày lớn hơn Đến ngày | C35: 1. Chọn Từ ngày sau Đến ngày. 2. Bấm "Tìm kiếm". | D35: Hệ thống tự điều chỉnh Từ ngày bằng Đến ngày, không báo lỗi và vẫn hiển thị kết quả. | F35: Passed | G35: 01/10/2026
A36: =IF(OR(B38<>"",D38<>""),"[" &TEXT($B$2,"##")&"-"&TEXT(25,"00")&"]","") -> [Module2-25] | B36: Phân trang khi có hơn 10 lượt dò | C36: 1. Dùng bộ lọc trả về hơn 10 lượt dò. 2. Xem danh sách và chuyển trang. | D36: Mỗi trang tối đa 10 dòng; hiển thị "Tổng cộng N lượt dò - trang x/y"; có thanh phân trang, khi chuyển trang vẫn giữ nguyên bộ lọc. | E36: Cần hơn 10 lượt dò khớp bộ lọc | F36: Passed | G36: 01/10/2026
A37: =IF(OR(B39<>"",D39<>""),"[" &TEXT($B$2,"##")&"-"&TEXT(26,"00")&"]","") -> [Module2-26] | B37: Chỉ xem được lịch sử của chính mình | C37: 1. USER A dò vé thành công. 2. Đăng xuất, đăng nhập USER B, vào "Lịch sử dò vé". | D37: USER B không thấy các lượt dò của USER A. | E37: Cần 2 tài khoản USER | F37: Passed | G37: 01/10/2026
A38: =IF(OR(B36<>"",D36<>""),"[" &TEXT($B$2,"##")&"-"&TEXT(27,"00")&"]","") -> [Module2-27] | B38: Chọn ngày trong tương lai | C38: 1. Chọn Từ ngày hoặc Đến ngày sau ngày hiện tại. 2. Bấm "Tìm kiếm". | D38: Hiển thị lỗi "Giá trị phải là ngày hiện tại hoặc sớm hơn."; không thực hiện tìm kiếm. | F38: Passed | G38: 01/10/2026
A39: =IF(OR(B37<>"",D37<>""),"[" &TEXT($B$2,"##")&"-"&TEXT(28,"00")&"]","") -> [Module2-28] | B39: Không có lượt dò phù hợp bộ lọc | C39: 1. Chọn bộ lọc chắc chắn không có lượt dò nào. 2. Bấm "Tìm kiếm". | D39: Hiển thị "Bạn chưa dò vé số lần nào phù hợp với bộ lọc đã chọn." | F39: Passed | G39: 01/10/2026

Sheet Test Report
B1: TEST REPORT
B3: Project Name | C3: Dò vé số | E3: Creator | G3: DucNVFX14814
B4: Project Code | C4: Lab301x | E4: Reviewer/Approver | G4: ToanHK(Mentor)
B5: Document Code | C5: =C4&"_"&"CN3_TestCase"&"_"&"v1.0" -> Lab301x_CN3_TestCase_v1.0 | E5: Issue Date | G5: 01/10/2026
B6: Notes | C6: Release 1 gồm 2 module: Module1 (NO_USER - Dò vé số), Module2 (USER - Dò vé số, Lịch sử dò vé).
B9: No | C9: Module code | D9: Pass | E9: Fail | F9: Untested | G9: Blocked | H9: Skipped | I9: Number of test cases
B10: 1 | C10: =Module1!B2 -> Module1 | D10: =Module1!A6 -> 16 | E10: =Module1!B6 -> 0 | F10: =Module1!C6 -> 0 | G10: =Module1!D6 -> 0 | H10: =Module1!E6 -> 0 | I10: =Module1!F6 -> 16
B11: 2 | C11: =Module2!B2 -> Module2 | D11: =Module2!A6 -> 28 | E11: =Module2!B6 -> 0 | F11: =Module2!C6 -> 0 | G11: =Module2!D6 -> 0 | H11: =Module2!E6 -> 0 | I11: =Module2!F6 -> 28
C13: Sub total | D13: =SUM(D10:D12) -> 44 | E13: =SUM(E10:E12) -> 0 | F13: =SUM(F10:F12) -> 0 | G13: =SUM(G10:G12) -> 0 | H13: =SUM(H10:H12) -> 0 | I13: =SUM(I10:I12) -> 44
C15: Test coverage | E15: =IFERROR((D13+E13)*100/(I13-H13-G13),0) -> 100 | F15: %
C16: Test successful coverage | E16: =IFERROR(D13*100/(D13+E13),0) -> 100 | F16: %
